<?xml version='1.0'?>
<sdf version='1.4'>
  <model name="my_robot">
        <static>false</static>
 <link name='chassis'>
            <pose>0 0 .1325 0 0 0</pose>     

            <collision name='collision'>
              <geometry>
                <box>
                  <size>.27 .12 .135</size>
                </box>
              </geometry>
            </collision>

            <visual name='visual'>
              <geometry>
                <box>
                  <size>.27 .12 .135</size>
                </box>
              </geometry>
            </visual>
 	</link>
 
      <link name="FL_wheel">
        <pose>0.155 0.13 0.0625 0 1.5707 1.5707</pose>
        <collision name="collision">
          <geometry>
            <cylinder>
              <radius>.0625</radius>
              <length>.05</length>
            </cylinder>
          </geometry>
        </collision>
        <visual name="visual">
          <geometry>
            <cylinder>
              <radius>.0625</radius>
              <length>.05</length>
            </cylinder>
          </geometry>
        </visual>
      </link>

 <link name="FR_wheel">
        <pose>0.155 -0.13 0.0625 0 1.5707 1.5707</pose>
        <collision name="collision">
          <geometry>
            <cylinder>
              <radius>.0625</radius>
              <length>.05</length>
            </cylinder>
          </geometry>
        </collision>
        <visual name="visual">
          <geometry>
            <cylinder>
              <radius>.0625</radius>
              <length>.05</length>
            </cylinder>
          </geometry>
        </visual>
      </link>

 <link name="BL_wheel">
        <pose>-0.155 0.13 0.0625 0 1.5707 1.5707</pose>
        <collision name="collision">
          <geometry>
            <cylinder>
              <radius>.0625</radius>
              <length>.05</length>
            </cylinder>
          </geometry>
        </collision>
        <visual name="visual">
          <geometry>
            <cylinder>
              <radius>.0625</radius>
              <length>.05</length>
            </cylinder>
          </geometry>
        </visual>
      </link>

 <link name="BR_wheel">
        <pose>-0.155 -0.13 0.0625 0 1.5707 1.5707</pose>
        <collision name="collision">
          <geometry>
            <cylinder>
              <radius>.0625</radius>
              <length>.05</length>
            </cylinder>
          </geometry>
        </collision>
        <visual name="visual">
          <geometry>
            <cylinder>
              <radius>.0625</radius>
              <length>.05</length>
            </cylinder>
          </geometry>
        </visual>
      </link>


   <joint type="revolute" name="FL_wheel_hinge">
        <pose>0 0 -0.03 0 0 0</pose>
        <child>FL_wheel</child>
        <parent>chassis</parent>
        <axis>
          <xyz>0 1 0</xyz>
        </axis>
      </joint>

      <joint type="revolute" name="FR_wheel_hinge">
        <pose>5 0 0.03 0 0 0</pose>
        <child>FR_wheel</child>
        <parent>chassis</parent>
        <axis>
          <xyz>0 1 0</xyz>
        </axis>
      </joint>

 <joint type="revolute" name="BL_wheel_hinge">
        <pose>0 0 -0.03 0 0 0</pose>
        <child>BL_wheel</child>
        <parent>chassis</parent>
        <axis>
          <xyz>0 1 0</xyz>
        </axis>
      </joint>

      <joint type="revolute" name="BR_wheel_hinge">
        <pose>0 0 0.03 0 0 0</pose>
        <child>BR_wheel</child>
        <parent>chassis</parent>
        <axis>
          <xyz>0 1 0</xyz>
        </axis>
      </joint>



  </model>
</sdf>
